Workbook

Sheet 1 - FILL YOUR COSTS
B1: STR Pricing Calculator — Single Property | F1: =C14+C25+C39 -> 0
B2: Fill YELLOW cells only. Column D explains each item. Then go to → 2 - YOUR RESULTS | F2: =C14 -> 0
F3: =C25 -> 0
B4: YOUR PROPERTY | F4: =C39 -> 0
B5: Property / unit name | F5: =C38 -> 1
F6: =C34 -> 0
B7: FIXED COSTS — paid every month even with zero bookings
B8: Cost item | C8: AED / month | D8: What is this?
B9: Rent / monthly lease | D9: The amount you pay your landlord each month
B10: Internet (Du / Etisalat / Virgin) | D10: Your fixed broadband plan — e.g. AED 229–375/month
B11: Insurance | D11: Home, contents or liability insurance — e.g. AED 44–100/month
B12: DTCM permit (annual fee ÷ 12) | D12: Your annual tourist licence cost divided by 12
B13: Other fixed cost (optional) | D13: e.g. building management fee, parking — or leave as 0
B14: Fixed costs subtotal | C14: =SUM(C9:C13) -> 0 | D14: Auto-calculated — do not edit
B16: VARIABLE COSTS — change month to month with bookings
B17: Cost item | C17: AED / month (avg) | D17: Tip
B18: DEWA (electricity) | D18: Use your 3-month average — typically AED 500–1,100/month
B19: Mpower / district chiller | D19: If your building has district cooling — else put 0
B20: Cleaning company payout | D20: What you pay your cleaning company on average per month
B21: Consumables (toiletries, welcome pack, coffee) | D21: Everything you restock for guests — e.g. AED 50–150
B22: Guest care / call-outs | D22: Lockouts, issues, last-minute extras — e.g. AED 50–100
B23: Maintenance (3-month rolling average) | D23: Minor repairs, upkeep — use a 3-month rolling average
B24: Miscellaneous | D24: Anything small that doesn't fit above — e.g. AED 100–200
B25: Variable costs subtotal | C25: =SUM(C18:C24) -> 0 | D25: Auto-calculated — do not edit
B27: BUSINESS OVERHEAD — automatically shared across your units
C28: AED / month
B29: Software (Hostaway, PriceLabs, Quickbooks…) | D29: All software you use — pro-rated if shared across units
B30: Staff / VA / property manager share | D30: Your total team cost — will be split across units below
B31: Licences & accounting (DED, DTCM, accountant) | D31: Annual fees divided by 12 — pro-rated share
B32: Marketing (Google Ads, listing boosts, etc.) | D32: Monthly average across all your marketing spend
B33: Other overhead (optional) | D33: Anything else — or leave 0
B34: Total monthly business overhead | C34: =SUM(C29:C33) -> 0 | D34: Your total — will be split by number of units below
B36: OVERHEAD ALLOCATION — how overhead is split across your units
B37: Business overhead (software, staff, admin) should be split equally across all the units you manage — not loaded entirely onto one unit. If you only manage 1 unit, enter 1 below and the full overhead applies. If you manage more, this calculator automatically allocates only your fair share to this property.
B38: Number of active units you manage (enter 1 if only this property) | C38: 1 | D38: If you only manage 1 unit, enter 1 — full overhead applies. If you manage more, enter the total. Overhead divides automatically.
B39: Allocated overhead for THIS unit (auto-calculated) | C39: =IFERROR(IF(C38<=0,C34,C34/C38),C34) -> 0 | D39: This is what gets added to your break-even — not the full overhead total.
B41: TOTAL MONTHLY COST FOR THIS UNIT | C41: =C14+C25+C39 -> 0 | D41: Fixed costs + Variable costs + Allocated overhead ✓ Now go to tab → 2 - YOUR RESULTS

Sheet 2 - YOUR RESULTS
B1: Your Results — Break-Even, Pricing Floor & PriceLabs Settings
B2: All numbers pull automatically from tab 1. Fill the 2 yellow cells below — defaults work for most Dubai properties.
B4: YOUR COST SUMMARY (auto from tab 1 — nothing to fill here)
B5: Fixed costs / month | C5: ='1 - FILL YOUR COSTS'!F2 -> 0 | D5: Rent, internet, insurance, DTCM
B6: Variable costs / month | C6: ='1 - FILL YOUR COSTS'!F3 -> 0 | D6: DEWA, cleaning, maintenance, ops
B7: Overhead allocated to this unit | C7: ='1 - FILL YOUR COSTS'!F4 -> 0 | D7: Your fair share — total overhead ÷ number of units
B8: TOTAL COST FOR THIS UNIT | C8: ='1 - FILL YOUR COSTS'!F1 -> 0 | D8: Fixed + variable + allocated overhead
B9: Overhead shown above is your allocated share only (total overhead ÷ number of units you manage). This means break-even reflects the true cost of THIS unit, not your whole business.
B11: YOUR TARGETS — 2 cells to fill
B12: Target occupied nights per month | C12: 26 | D12: Default = 26 nights (85% occupancy on 31 days). After your free consultation, Oasis Revenue Lab will set your personalised target.
B13: Safety buffer above break-even (%) | C13: 0.15 | D13: Default = 15% (standard Dubai STR). New listing → 20%. High competition → 10%. We'll personalise this on your free consultation call.
B14: Want your personalised targets? Book a free call → WhatsApp +971527604550 | info@luxoasisholidayhomes.com | luxoasisholidayhomes.com
B16: YOUR KEY NUMBERS
B17: Break-even nightly rate | C17: =IFERROR('1 - FILL YOUR COSTS'!F1/C12,"") -> 0 | D17: Minimum rate to cover ALL costs — below this you lose money
B18: Your pricing floor (set this in PriceLabs as Minimum Price) | C18: =IFERROR(('1 - FILL YOUR COSTS'!F1/C12)*(1+C13),"") -> 0 | D18: Break-even + safety buffer = never accept below this
B19: Fixed cost per night | C19: =IFERROR('1 - FILL YOUR COSTS'!F2/C12,"") -> 0 | D19: Rent + fixed costs spread across your booked nights
B20: Variable cost per night | C20: =IFERROR('1 - FILL YOUR COSTS'!F3/C12,"") -> 0 | D20: Utilities + cleaning + ops per booked night
B21: Allocated overhead per night | C21: =IFERROR('1 - FILL YOUR COSTS'!F4/C12,"") -> 0 | D21: Your overhead share for this unit per booked night
B22: Estimated monthly profit at pricing floor | C22: =IFERROR(('1 - FILL YOUR COSTS'!F1/C12)*(1+C13)*C12-'1 - FILL YOUR COSTS'!F1,"") -> 0 | D22: Revenue at floor price × target nights, minus total costs
B24: PRICELABS SETTINGS — copy these 6 numbers into PriceLabs
B25: Rule | C25: AED / night | D25: When to apply
B26: 1. Minimum price (your hard floor) | C26: =IFERROR(('1 - FILL YOUR COSTS'!F1/C12)*(1+C13),"") -> 0 | D26: Set as 'Minimum Price' in PriceLabs. Never accept below this.
B27: 2. Last-minute floor (3 days or fewer) | C27: =IFERROR('1 - FILL YOUR COSTS'!F1/C12*1.05,"") -> 0 | D27: Last-minute discounts stop here — 5% above break-even.
B28: 3. Orphan gap fill (1–2 night gaps) | C28: =IFERROR('1 - FILL YOUR COSTS'!F1/C12,"") -> 0 | D28: Fill short gaps at break-even — better than staying empty.
B29: 4. Low-season base price (Jun–Sep) | C29: =IFERROR('1 - FILL YOUR COSTS'!F1/C12*1.2,"") -> 0 | D29: Slow months floor — 20% above break-even minimum.
B30: 5. Weekend floor (Fri & Sat nights) | C30: =IFERROR('1 - FILL YOUR COSTS'!F1/C12*1.35,"") -> 0 | D30: Weekend premium — minimum 35% above break-even.
B31: 6. Peak season minimum (Nov, Dec, New Year) | C31: =IFERROR('1 - FILL YOUR COSTS'!F1/C12*1.6,"") -> 0 | D31: Peak periods — push hard, floor at 60% above break-even.
B33: OCCUPANCY SENSITIVITY — how your cost per night changes at different booking levels
B34: Nights booked | C34: Occupancy % | D34: Cost / night (at scenario occupancy) | E34: Pricing floor (scenario-specific) | F34: Monthly profit (at target floor price) | G34: Status
B35: 10 nights | C35: =10/31 -> 0.32258065 | D35: =IFERROR('1 - FILL YOUR COSTS'!F1/10,"") -> 0 | E35: =IFERROR('1 - FILL YOUR COSTS'!F1/10*(1+C$13),"") -> 0 | F35: =IFERROR(('1 - FILL YOUR COSTS'!F1/C$12)*(1+C$13)*10-'1 - FILL YOUR COSTS'!F1,"") -> 0 | G35: =IFERROR(IF(10/C$12<0.5,"Loss-making",IF(10/C$12<0.6,"Loss-making",IF(10/C$12<0.65,"Borderline",IF(10/C$12<0.72,"Marginal",IF(10/C$12<0.82,"Profitable",IF(10/C$12<0.92,"Strong","Peak")))))),"") -> Loss-making
B36: 15 nights | C36: =15/31 -> 0.48387097 | D36: =IFERROR('1 - FILL YOUR COSTS'!F1/15,"") -> 0 | E36: =IFERROR('1 - FILL YOUR COSTS'!F1/15*(1+C$13),"") -> 0 | F36: =IFERROR(('1 - FILL YOUR COSTS'!F1/C$12)*(1+C$13)*15-'1 - FILL YOUR COSTS'!F1,"") -> 0 | G36: =IFERROR(IF(15/C$12<0.5,"Loss-making",IF(15/C$12<0.6,"Loss-making",IF(15/C$12<0.65,"Borderline",IF(15/C$12<0.72,"Marginal",IF(15/C$12<0.82,"Profitable",IF(15/C$12<0.92,"Strong","Peak")))))),"") -> Loss-making
B37: 18 nights | C37: =18/31 -> 0.58064516 | D37: =IFERROR('1 - FILL YOUR COSTS'!F1/18,"") -> 0 | E37: =IFERROR('1 - FILL YOUR COSTS'!F1/18*(1+C$13),"") -> 0 | F37: =IFERROR(('1 - FILL YOUR COSTS'!F1/C$12)*(1+C$13)*18-'1 - FILL YOUR COSTS'!F1,"") -> 0 | G37: =IFERROR(IF(18/C$12<0.5,"Loss-making",IF(18/C$12<0.6,"Loss-making",IF(18/C$12<0.65,"Borderline",IF(18/C$12<0.72,"Marginal",IF(18/C$12<0.82,"Profitable",IF(18/C$12<0.92,"Strong","Peak")))))),"") -> Marginal
B38: 20 nights | C38: =20/31 -> 0.64516129 | D38: =IFERROR('1 - FILL YOUR COSTS'!F1/20,"") -> 0 | E38: =IFERROR('1 - FILL YOUR COSTS'!F1/20*(1+C$13),"") -> 0 | F38: =IFERROR(('1 - FILL YOUR COSTS'!F1/C$12)*(1+C$13)*20-'1 - FILL YOUR COSTS'!F1,"") -> 0 | G38: =IFERROR(IF(20/C$12<0.5,"Loss-making",IF(20/C$12<0.6,"Loss-making",IF(20/C$12<0.65,"Borderline",IF(20/C$12<0.72,"Marginal",IF(20/C$12<0.82,"Profitable",IF(20/C$12<0.92,"Strong","Peak")))))),"") -> Profitable
B39: 22 nights | C39: =22/31 -> 0.70967742 | D39: =IFERROR('1 - FILL YOUR COSTS'!F1/22,"") -> 0 | E39: =IFERROR('1 - FILL YOUR COSTS'!F1/22*(1+C$13),"") -> 0 | F39: =IFERROR(('1 - FILL YOUR COSTS'!F1/C$12)*(1+C$13)*22-'1 - FILL YOUR COSTS'!F1,"") -> 0 | G39: =IFERROR(IF(22/C$12<0.5,"Loss-making",IF(22/C$12<0.6,"Loss-making",IF(22/C$12<0.65,"Borderline",IF(22/C$12<0.72,"Marginal",IF(22/C$12<0.82,"Profitable",IF(22/C$12<0.92,"Strong","Peak")))))),"") -> Strong
B40: 24 nights | C40: =24/31 -> 0.77419355 | D40: =IFERROR('1 - FILL YOUR COSTS'!F1/24,"") -> 0 | E40: =IFERROR('1 - FILL YOUR COSTS'!F1/24*(1+C$13),"") -> 0 | F40: =IFERROR(('1 - FILL YOUR COSTS'!F1/C$12)*(1+C$13)*24-'1 - FILL YOUR COSTS'!F1,"") -> 0 | G40: =IFERROR(IF(24/C$12<0.5,"Loss-making",IF(24/C$12<0.6,"Loss-making",IF(24/C$12<0.65,"Borderline",IF(24/C$12<0.72,"Marginal",IF(24/C$12<0.82,"Profitable",IF(24/C$12<0.92,"Strong","Peak")))))),"") -> Peak
B41: 26 nights | C41: =26/31 -> 0.83870968 | D41: =IFERROR('1 - FILL YOUR COSTS'!F1/26,"") -> 0 | E41: =IFERROR('1 - FILL YOUR COSTS'!F1/26*(1+C$13),"") -> 0 | F41: =IFERROR(('1 - FILL YOUR COSTS'!F1/C$12)*(1+C$13)*26-'1 - FILL YOUR COSTS'!F1,"") -> 0 | G41: =IFERROR(IF(26/C$12<0.5,"Loss-making",IF(26/C$12<0.6,"Loss-making",IF(26/C$12<0.65,"Borderline",IF(26/C$12<0.72,"Marginal",IF(26/C$12<0.82,"Profitable",IF(26/C$12<0.92,"Strong","Peak")))))),"") -> Peak
B42: 28 nights | C42: =28/31 -> 0.90322581 | D42: =IFERROR('1 - FILL YOUR COSTS'!F1/28,"") -> 0 | E42: =IFERROR('1 - FILL YOUR COSTS'!F1/28*(1+C$13),"") -> 0 | F42: =IFERROR(('1 - FILL YOUR COSTS'!F1/C$12)*(1+C$13)*28-'1 - FILL YOUR COSTS'!F1,"") -> 0 | G42: =IFERROR(IF(28/C$12<0.5,"Loss-making",IF(28/C$12<0.6,"Loss-making",IF(28/C$12<0.65,"Borderline",IF(28/C$12<0.72,"Marginal",IF(28/C$12<0.82,"Profitable",IF(28/C$12<0.92,"Strong","Peak")))))),"") -> Peak
B43: 30 nights | C43: =30/31 -> 0.96774194 | D43: =IFERROR('1 - FILL YOUR COSTS'!F1/30,"") -> 0 | E43: =IFERROR('1 - FILL YOUR COSTS'!F1/30*(1+C$13),"") -> 0 | F43: =IFERROR(('1 - FILL YOUR COSTS'!F1/C$12)*(1+C$13)*30-'1 - FILL YOUR COSTS'!F1,"") -> 0 | G43: =IFERROR(IF(30/C$12<0.5,"Loss-making",IF(30/C$12<0.6,"Loss-making",IF(30/C$12<0.65,"Borderline",IF(30/C$12<0.72,"Marginal",IF(30/C$12<0.82,"Profitable",IF(30/C$12<0.92,"Strong","Peak")))))),"") -> Peak
B44: 31 nights | C44: =31/31 -> 1 | D44: =IFERROR('1 - FILL YOUR COSTS'!F1/31,"") -> 0 | E44: =IFERROR('1 - FILL YOUR COSTS'!F1/31*(1+C$13),"") -> 0 | F44: =IFERROR(('1 - FILL YOUR COSTS'!F1/C$12)*(1+C$13)*31-'1 - FILL YOUR COSTS'!F1,"") -> 0 | G44: =IFERROR(IF(31/C$12<0.5,"Loss-making",IF(31/C$12<0.6,"Loss-making",IF(31/C$12<0.65,"Borderline",IF(31/C$12<0.72,"Marginal",IF(31/C$12<0.82,"Profitable",IF(31/C$12<0.92,"Strong","Peak")))))),"") -> Peak
B46: Oasis Revenue Lab — Professional Revenue Management for Dubai STR
...
